{
 "cells": [
  {
   "cell_type": "code",
   "execution_count": 1,
   "metadata": {},
   "outputs": [],
   "source": [
    "import os\n",
    "import numpy as np\n",
    "import pandas as pd\n",
    "from aeon.datasets import load_classification\n",
    "import warnings\n",
    "\n",
    "from utils.tools import create_directory\n",
    "from utils.constants import datasets"
   ]
  },
  {
   "cell_type": "code",
   "execution_count": 2,
   "metadata": {},
   "outputs": [
    {
     "name": "stdout",
     "output_type": "stream",
     "text": [
      "(275, 9, 144)\n"
     ]
    }
   ],
   "source": [
    "X_train, Y_train = load_classification(\"ArticularyWordRecognition\", split=\"train\")\n",
    "\n",
    "print(X_train.shape)"
   ]
  },
  {
   "cell_type": "code",
   "execution_count": 1,
   "metadata": {},
   "outputs": [
    {
     "name": "stderr",
     "output_type": "stream",
     "text": [
      "2024-04-09 16:46:29.421273: I tensorflow/core/platform/cpu_feature_guard.cc:210] This TensorFlow binary is optimized to use available CPU instructions in performance-critical operations.\n",
      "To enable the following instructions: AVX2 FMA, in other operations, rebuild TensorFlow with the appropriate compiler flags.\n",
      "2024-04-09 16:46:30.178253: W tensorflow/compiler/tf2tensorrt/utils/py_utils.cc:38] TF-TRT Warning: Could not find TensorRT\n"
     ]
    },
    {
     "name": "stdout",
     "output_type": "stream",
     "text": [
      "[Main] Problem: ArticularyWordRecognition\n"
     ]
    },
    {
     "name": "stderr",
     "output_type": "stream",
     "text": [
      "2024-04-09 16:46:31.377424: I external/local_xla/xla/stream_executor/cuda/cuda_executor.cc:998] successful NUMA node read from SysFS had negative value (-1), but there must be at least one NUMA node, so returning NUMA node zero. See more at https://github.com/torvalds/linux/blob/v6.0/Documentation/ABI/testing/sysfs-bus-pci#L344-L355\n",
      "2024-04-09 16:46:31.419995: I external/local_xla/xla/stream_executor/cuda/cuda_executor.cc:998] successful NUMA node read from SysFS had negative value (-1), but there must be at least one NUMA node, so returning NUMA node zero. See more at https://github.com/torvalds/linux/blob/v6.0/Documentation/ABI/testing/sysfs-bus-pci#L344-L355\n",
      "2024-04-09 16:46:31.420171: I external/local_xla/xla/stream_executor/cuda/cuda_executor.cc:998] successful NUMA node read from SysFS had negative value (-1), but there must be at least one NUMA node, so returning NUMA node zero. See more at https://github.com/torvalds/linux/blob/v6.0/Documentation/ABI/testing/sysfs-bus-pci#L344-L355\n",
      "2024-04-09 16:46:31.421168: I external/local_xla/xla/stream_executor/cuda/cuda_executor.cc:998] successful NUMA node read from SysFS had negative value (-1), but there must be at least one NUMA node, so returning NUMA node zero. See more at https://github.com/torvalds/linux/blob/v6.0/Documentation/ABI/testing/sysfs-bus-pci#L344-L355\n",
      "2024-04-09 16:46:31.421315: I external/local_xla/xla/stream_executor/cuda/cuda_executor.cc:998] successful NUMA node read from SysFS had negative value (-1), but there must be at least one NUMA node, so returning NUMA node zero. See more at https://github.com/torvalds/linux/blob/v6.0/Documentation/ABI/testing/sysfs-bus-pci#L344-L355\n",
      "2024-04-09 16:46:31.421443: I external/local_xla/xla/stream_executor/cuda/cuda_executor.cc:998] successful NUMA node read from SysFS had negative value (-1), but there must be at least one NUMA node, so returning NUMA node zero. See more at https://github.com/torvalds/linux/blob/v6.0/Documentation/ABI/testing/sysfs-bus-pci#L344-L355\n",
      "2024-04-09 16:46:31.474341: I external/local_xla/xla/stream_executor/cuda/cuda_executor.cc:998] successful NUMA node read from SysFS had negative value (-1), but there must be at least one NUMA node, so returning NUMA node zero. See more at https://github.com/torvalds/linux/blob/v6.0/Documentation/ABI/testing/sysfs-bus-pci#L344-L355\n",
      "2024-04-09 16:46:31.474521: I external/local_xla/xla/stream_executor/cuda/cuda_executor.cc:998] successful NUMA node read from SysFS had negative value (-1), but there must be at least one NUMA node, so returning NUMA node zero. See more at https://github.com/torvalds/linux/blob/v6.0/Documentation/ABI/testing/sysfs-bus-pci#L344-L355\n",
      "2024-04-09 16:46:31.474661: I external/local_xla/xla/stream_executor/cuda/cuda_executor.cc:998] successful NUMA node read from SysFS had negative value (-1), but there must be at least one NUMA node, so returning NUMA node zero. See more at https://github.com/torvalds/linux/blob/v6.0/Documentation/ABI/testing/sysfs-bus-pci#L344-L355\n",
      "2024-04-09 16:46:31.474762: I tensorflow/core/common_runtime/gpu/gpu_device.cc:1928] Created device /job:localhost/replica:0/task:0/device:GPU:0 with 1739 MB memory:  -> device: 0, name: Quadro P400, pci bus id: 0000:01:00.0, compute capability: 6.1\n",
      "WARNING: All log messages before absl::InitializeLog() is called are written to STDERR\n",
      "I0000 00:00:1712673992.263095 2290827 service.cc:145] XLA service 0x7a046c00cd70 initialized for platform CUDA (this does not guarantee that XLA will be used). Devices:\n",
      "I0000 00:00:1712673992.263169 2290827 service.cc:153]   StreamExecutor device (0): Quadro P400, Compute Capability 6.1\n",
      "2024-04-09 16:46:32.273231: I tensorflow/compiler/mlir/tensorflow/utils/dump_mlir_util.cc:268] disabling MLIR crash reproducer, set env var `MLIR_CRASH_REPRODUCER_DIRECTORY` to enable.\n",
      "2024-04-09 16:46:32.336828: I external/local_xla/xla/stream_executor/cuda/cuda_dnn.cc:465] Loaded cuDNN version 8907\n"
     ]
    },
    {
     "name": "stdout",
     "output_type": "stream",
     "text": [
      "\u001b[1m1/9\u001b[0m \u001b[32m━━\u001b[0m\u001b[37m━━━━━━━━━━━━━━━━━━\u001b[0m \u001b[1m18s\u001b[0m 2s/step"
     ]
    },
    {
     "name": "stderr",
     "output_type": "stream",
     "text": [
      "I0000 00:00:1712673994.381445 2290827 device_compiler.h:188] Compiled cluster using XLA!  This line is logged at most once for the lifetime of the process.\n"
     ]
    },
    {
     "name": "stdout",
     "output_type": "stream",
     "text": [
      "\u001b[1m9/9\u001b[0m \u001b[32m━━━━━━━━━━━━━━━━━━━━\u001b[0m\u001b[37m\u001b[0m \u001b[1m4s\u001b[0m 259ms/step\n",
      "1.0\n",
      "[Main] Problem: BasicMotions\n",
      "\u001b[1m2/2\u001b[0m \u001b[32m━━━━━━━━━━━━━━━━━━━━\u001b[0m\u001b[37m\u001b[0m \u001b[1m4s\u001b[0m 2s/step\n",
      "1.0\n",
      "[Main] Problem: Cricket\n",
      "WARNING:tensorflow:5 out of the last 12 calls to <function TensorFlowTrainer.make_predict_function.<locals>.one_step_on_data_distributed at 0x7a053d447400> triggered tf.function retracing. Tracing is expensive and the excessive number of tracings could be due to (1) creating @tf.function repeatedly in a loop, (2) passing tensors with different shapes, (3) passing Python objects instead of tensors. For (1), please define your @tf.function outside of the loop. For (2), @tf.function has reduce_retracing=True option that can avoid unnecessary retracing. For (3), please refer to https://www.tensorflow.org/guide/function#controlling_retracing and https://www.tensorflow.org/api_docs/python/tf/function for  more details.\n",
      "\u001b[1m1/4\u001b[0m \u001b[32m━━━━━\u001b[0m\u001b[37m━━━━━━━━━━━━━━━\u001b[0m \u001b[1m5s\u001b[0m 2s/stepWARNING:tensorflow:6 out of the last 15 calls to <function TensorFlowTrainer.make_predict_function.<locals>.one_step_on_data_distributed at 0x7a053d447400> triggered tf.function retracing. Tracing is expensive and the excessive number of tracings could be due to (1) creating @tf.function repeatedly in a loop, (2) passing tensors with different shapes, (3) passing Python objects instead of tensors. For (1), please define your @tf.function outside of the loop. For (2), @tf.function has reduce_retracing=True option that can avoid unnecessary retracing. For (3), please refer to https://www.tensorflow.org/guide/function#controlling_retracing and https://www.tensorflow.org/api_docs/python/tf/function for  more details.\n",
      "\u001b[1m4/4\u001b[0m \u001b[32m━━━━━━━━━━━━━━━━━━━━\u001b[0m\u001b[37m\u001b[0m \u001b[1m4s\u001b[0m 783ms/step\n",
      "1.0\n",
      "[Main] Problem: Epilepsy\n",
      "\u001b[1m5/5\u001b[0m \u001b[32m━━━━━━━━━━━━━━━━━━━━\u001b[0m\u001b[37m\u001b[0m \u001b[1m4s\u001b[0m 481ms/step\n",
      "0.7956204379562044\n",
      "[Main] Problem: ERing\n",
      "\u001b[1m1/1\u001b[0m \u001b[32m━━━━━━━━━━━━━━━━━━━━\u001b[0m\u001b[37m\u001b[0m \u001b[1m2s\u001b[0m 2s/step\n",
      "1.0\n",
      "[Main] Problem: EthanolConcentration\n",
      "\u001b[1m9/9\u001b[0m \u001b[32m━━━━━━━━━━━━━━━━━━━━\u001b[0m\u001b[37m\u001b[0m \u001b[1m4s\u001b[0m 297ms/step\n",
      "0.685823754789272\n",
      "[Main] Problem: FaceDetection\n",
      "\u001b[1m185/185\u001b[0m \u001b[32m━━━━━━━━━━━━━━━━━━━━\u001b[0m\u001b[37m\u001b[0m \u001b[1m15s\u001b[0m 62ms/step\n",
      "0.999830220713073\n",
      "[Main] Problem: FingerMovements\n",
      "\u001b[1m10/10\u001b[0m \u001b[32m━━━━━━━━━━━━━━━━━━━━\u001b[0m\u001b[37m\u001b[0m \u001b[1m4s\u001b[0m 262ms/step\n",
      "0.9778481012658228\n",
      "[Main] Problem: HandMovementDirection\n",
      "\u001b[1m5/5\u001b[0m \u001b[32m━━━━━━━━━━━━━━━━━━━━\u001b[0m\u001b[37m\u001b[0m \u001b[1m2s\u001b[0m 14ms/step\n",
      "0.94375\n",
      "[Main] Problem: Handwriting\n",
      "\u001b[1m5/5\u001b[0m \u001b[32m━━━━━━━━━━━━━━━━━━━━\u001b[0m\u001b[37m\u001b[0m \u001b[1m3s\u001b[0m 473ms/step\n",
      "1.0\n",
      "[Main] Problem: Heartbeat\n",
      "\u001b[1m7/7\u001b[0m \u001b[32m━━━━━━━━━━━━━━━━━━━━\u001b[0m\u001b[37m\u001b[0m \u001b[1m8s\u001b[0m 544ms/step\n",
      "0.9901960784313726\n",
      "[Main] Problem: Libras\n",
      "\u001b[1m6/6\u001b[0m \u001b[32m━━━━━━━━━━━━━━━━━━━━\u001b[0m\u001b[37m\u001b[0m \u001b[1m4s\u001b[0m 369ms/step\n",
      "0.5333333333333333\n",
      "[Main] Problem: LSST\n",
      "\u001b[1m77/77\u001b[0m \u001b[32m━━━━━━━━━━━━━━━━━━━━\u001b[0m\u001b[37m\u001b[0m \u001b[1m3s\u001b[0m 29ms/step\n",
      "0.6026840178934526\n",
      "[Main] Problem: NATOPS\n",
      "\u001b[1m6/6\u001b[0m \u001b[32m━━━━━━━━━━━━━━━━━━━━\u001b[0m\u001b[37m\u001b[0m \u001b[1m4s\u001b[0m 395ms/step\n",
      "0.9944444444444445\n",
      "[Main] Problem: PEMS-SF\n"
     ]
    },
    {
     "name": "stderr",
     "output_type": "stream",
     "text": [
      "2024-04-09 16:48:11.861609: W external/local_tsl/tsl/framework/bfc_allocator.cc:296] Allocator (GPU_0_bfc) ran out of memory trying to allocate 1.07GiB with freed_by_count=0. The caller indicates that this is not a failure, but this may mean that there could be performance gains if more memory were available.\n",
      "2024-04-09 16:48:11.864794: W tensorflow/core/framework/op_kernel.cc:1839] OP_REQUIRES failed at xla_ops.cc:580 : UNKNOWN: Failed to determine best cudnn convolution algorithm for:\n",
      "%cudnn-conv-bias-activation.22 = (f32[32,64,963,144]{3,2,1,0}, u8[0]{0}) custom-call(f32[32,1,970,144]{3,2,1,0} %pad.3, f32[64,1,8,1]{3,2,1,0} %transpose.20, f32[64]{0} %arg2.3), window={size=8x1}, dim_labels=bf01_oi01->bf01, custom_call_target=\"__cudnn$convBiasActivationForward\", metadata={op_type=\"Conv2D\" op_name=\"functional_1_1/conv2d_1/convolution\" source_file=\"/home/elnur/Desktop/Disjoint-CNN/env/lib/python3.10/site-packages/tensorflow/python/framework/ops.py\" source_line=1177}, backend_config={\"operation_queue_id\":\"0\",\"wait_on_operation_queues\":[],\"cudnn_conv_backend_config\":{\"conv_result_scale\":1,\"activation_mode\":\"kNone\",\"side_input_scale\":0,\"leakyrelu_alpha\":0}}\n",
      "\n",
      "Original error: RESOURCE_EXHAUSTED: Out of memory while trying to allocate 1152778240 bytes.\n",
      "\n",
      "To ignore this failure and try to use a fallback algorithm (which may have suboptimal performance), use XLA_FLAGS=--xla_gpu_strict_conv_algorithm_picker=false.  Please also file a bug for the root cause of failing autotuning.\n",
      "2024-04-09 16:48:11.864841: W tensorflow/core/framework/local_rendezvous.cc:404] Local rendezvous is aborting with status: UNKNOWN: Failed to determine best cudnn convolution algorithm for:\n",
      "%cudnn-conv-bias-activation.22 = (f32[32,64,963,144]{3,2,1,0}, u8[0]{0}) custom-call(f32[32,1,970,144]{3,2,1,0} %pad.3, f32[64,1,8,1]{3,2,1,0} %transpose.20, f32[64]{0} %arg2.3), window={size=8x1}, dim_labels=bf01_oi01->bf01, custom_call_target=\"__cudnn$convBiasActivationForward\", metadata={op_type=\"Conv2D\" op_name=\"functional_1_1/conv2d_1/convolution\" source_file=\"/home/elnur/Desktop/Disjoint-CNN/env/lib/python3.10/site-packages/tensorflow/python/framework/ops.py\" source_line=1177}, backend_config={\"operation_queue_id\":\"0\",\"wait_on_operation_queues\":[],\"cudnn_conv_backend_config\":{\"conv_result_scale\":1,\"activation_mode\":\"kNone\",\"side_input_scale\":0,\"leakyrelu_alpha\":0}}\n",
      "\n",
      "Original error: RESOURCE_EXHAUSTED: Out of memory while trying to allocate 1152778240 bytes.\n",
      "\n",
      "To ignore this failure and try to use a fallback algorithm (which may have suboptimal performance), use XLA_FLAGS=--xla_gpu_strict_conv_algorithm_picker=false.  Please also file a bug for the root cause of failing autotuning.\n",
      "\t [[{{node StatefulPartitionedCall}}]]\n"
     ]
    },
    {
     "ename": "UnknownError",
     "evalue": "Graph execution error:\n\nDetected at node StatefulPartitionedCall defined at (most recent call last):\n  File \"/usr/lib/python3.10/runpy.py\", line 196, in _run_module_as_main\n\n  File \"/usr/lib/python3.10/runpy.py\", line 86, in _run_code\n\n  File \"/home/elnur/Desktop/Disjoint-CNN/env/lib/python3.10/site-packages/ipykernel_launcher.py\", line 18, in <module>\n\n  File \"/home/elnur/Desktop/Disjoint-CNN/env/lib/python3.10/site-packages/traitlets/config/application.py\", line 1075, in launch_instance\n\n  File \"/home/elnur/Desktop/Disjoint-CNN/env/lib/python3.10/site-packages/ipykernel/kernelapp.py\", line 739, in start\n\n  File \"/home/elnur/Desktop/Disjoint-CNN/env/lib/python3.10/site-packages/tornado/platform/asyncio.py\", line 205, in start\n\n  File \"/usr/lib/python3.10/asyncio/base_events.py\", line 603, in run_forever\n\n  File \"/usr/lib/python3.10/asyncio/base_events.py\", line 1909, in _run_once\n\n  File \"/usr/lib/python3.10/asyncio/events.py\", line 80, in _run\n\n  File \"/home/elnur/Desktop/Disjoint-CNN/env/lib/python3.10/site-packages/ipykernel/kernelbase.py\", line 545, in dispatch_queue\n\n  File \"/home/elnur/Desktop/Disjoint-CNN/env/lib/python3.10/site-packages/ipykernel/kernelbase.py\", line 534, in process_one\n\n  File \"/home/elnur/Desktop/Disjoint-CNN/env/lib/python3.10/site-packages/ipykernel/kernelbase.py\", line 437, in dispatch_shell\n\n  File \"/home/elnur/Desktop/Disjoint-CNN/env/lib/python3.10/site-packages/ipykernel/ipkernel.py\", line 359, in execute_request\n\n  File \"/home/elnur/Desktop/Disjoint-CNN/env/lib/python3.10/site-packages/ipykernel/kernelbase.py\", line 778, in execute_request\n\n  File \"/home/elnur/Desktop/Disjoint-CNN/env/lib/python3.10/site-packages/ipykernel/ipkernel.py\", line 446, in do_execute\n\n  File \"/home/elnur/Desktop/Disjoint-CNN/env/lib/python3.10/site-packages/ipykernel/zmqshell.py\", line 549, in run_cell\n\n  File \"/home/elnur/Desktop/Disjoint-CNN/env/lib/python3.10/site-packages/IPython/core/interactiveshell.py\", line 3075, in run_cell\n\n  File \"/home/elnur/Desktop/Disjoint-CNN/env/lib/python3.10/site-packages/IPython/core/interactiveshell.py\", line 3130, in _run_cell\n\n  File \"/home/elnur/Desktop/Disjoint-CNN/env/lib/python3.10/site-packages/IPython/core/async_helpers.py\", line 129, in _pseudo_sync_runner\n\n  File \"/home/elnur/Desktop/Disjoint-CNN/env/lib/python3.10/site-packages/IPython/core/interactiveshell.py\", line 3334, in run_cell_async\n\n  File \"/home/elnur/Desktop/Disjoint-CNN/env/lib/python3.10/site-packages/IPython/core/interactiveshell.py\", line 3517, in run_ast_nodes\n\n  File \"/home/elnur/Desktop/Disjoint-CNN/env/lib/python3.10/site-packages/IPython/core/interactiveshell.py\", line 3577, in run_code\n\n  File \"/tmp/ipykernel_2290774/4282388530.py\", line 25, in <module>\n\n  File \"/home/elnur/Desktop/Disjoint-CNN/env/lib/python3.10/site-packages/keras/src/utils/traceback_utils.py\", line 118, in error_handler\n\n  File \"/home/elnur/Desktop/Disjoint-CNN/env/lib/python3.10/site-packages/keras/src/backend/tensorflow/trainer.py\", line 513, in predict\n\n  File \"/home/elnur/Desktop/Disjoint-CNN/env/lib/python3.10/site-packages/keras/src/backend/tensorflow/trainer.py\", line 212, in one_step_on_data_distributed\n\nFailed to determine best cudnn convolution algorithm for:\n%cudnn-conv-bias-activation.22 = (f32[32,64,963,144]{3,2,1,0}, u8[0]{0}) custom-call(f32[32,1,970,144]{3,2,1,0} %pad.3, f32[64,1,8,1]{3,2,1,0} %transpose.20, f32[64]{0} %arg2.3), window={size=8x1}, dim_labels=bf01_oi01->bf01, custom_call_target=\"__cudnn$convBiasActivationForward\", metadata={op_type=\"Conv2D\" op_name=\"functional_1_1/conv2d_1/convolution\" source_file=\"/home/elnur/Desktop/Disjoint-CNN/env/lib/python3.10/site-packages/tensorflow/python/framework/ops.py\" source_line=1177}, backend_config={\"operation_queue_id\":\"0\",\"wait_on_operation_queues\":[],\"cudnn_conv_backend_config\":{\"conv_result_scale\":1,\"activation_mode\":\"kNone\",\"side_input_scale\":0,\"leakyrelu_alpha\":0}}\n\nOriginal error: RESOURCE_EXHAUSTED: Out of memory while trying to allocate 1152778240 bytes.\n\nTo ignore this failure and try to use a fallback algorithm (which may have suboptimal performance), use XLA_FLAGS=--xla_gpu_strict_conv_algorithm_picker=false.  Please also file a bug for the root cause of failing autotuning.\n\t [[{{node StatefulPartitionedCall}}]] [Op:__inference_one_step_on_data_distributed_22732]",
     "output_type": "error",
     "traceback": [
      "\u001b[0;31m---------------------------------------------------------------------------\u001b[0m",
      "\u001b[0;31mUnknownError\u001b[0m                              Traceback (most recent call last)",
      "Cell \u001b[0;32mIn[1], line 25\u001b[0m\n\u001b[1;32m     23\u001b[0m X_train, y_train \u001b[38;5;241m=\u001b[39m load_classification(problem, split\u001b[38;5;241m=\u001b[39m\u001b[38;5;124m'\u001b[39m\u001b[38;5;124mtrain\u001b[39m\u001b[38;5;124m'\u001b[39m)\n\u001b[1;32m     24\u001b[0m model \u001b[38;5;241m=\u001b[39m keras\u001b[38;5;241m.\u001b[39mmodels\u001b[38;5;241m.\u001b[39mload_model(output_directory \u001b[38;5;241m+\u001b[39m \u001b[38;5;124m'\u001b[39m\u001b[38;5;124mbest_model.keras\u001b[39m\u001b[38;5;124m'\u001b[39m)\n\u001b[0;32m---> 25\u001b[0m preds \u001b[38;5;241m=\u001b[39m \u001b[43mmodel\u001b[49m\u001b[38;5;241;43m.\u001b[39;49m\u001b[43mpredict\u001b[49m\u001b[43m(\u001b[49m\u001b[43mX_train\u001b[49m\u001b[43m)\u001b[49m\n\u001b[1;32m     26\u001b[0m preds\u001b[38;5;241m=\u001b[39mnp\u001b[38;5;241m.\u001b[39margmax(preds,axis\u001b[38;5;241m=\u001b[39m\u001b[38;5;241m1\u001b[39m)\n\u001b[1;32m     27\u001b[0m y_train \u001b[38;5;241m=\u001b[39m encoder\u001b[38;5;241m.\u001b[39mfit_transform(y_train)\n",
      "File \u001b[0;32m~/Desktop/Disjoint-CNN/env/lib/python3.10/site-packages/keras/src/utils/traceback_utils.py:123\u001b[0m, in \u001b[0;36mfilter_traceback.<locals>.error_handler\u001b[0;34m(*args, **kwargs)\u001b[0m\n\u001b[1;32m    120\u001b[0m     filtered_tb \u001b[38;5;241m=\u001b[39m _process_traceback_frames(e\u001b[38;5;241m.\u001b[39m__traceback__)\n\u001b[1;32m    121\u001b[0m     \u001b[38;5;66;03m# To get the full stack trace, call:\u001b[39;00m\n\u001b[1;32m    122\u001b[0m     \u001b[38;5;66;03m# `keras.config.disable_traceback_filtering()`\u001b[39;00m\n\u001b[0;32m--> 123\u001b[0m     \u001b[38;5;28;01mraise\u001b[39;00m e\u001b[38;5;241m.\u001b[39mwith_traceback(filtered_tb) \u001b[38;5;28;01mfrom\u001b[39;00m \u001b[38;5;28;01mNone\u001b[39;00m\n\u001b[1;32m    124\u001b[0m \u001b[38;5;28;01mfinally\u001b[39;00m:\n\u001b[1;32m    125\u001b[0m     \u001b[38;5;28;01mdel\u001b[39;00m filtered_tb\n",
      "File \u001b[0;32m~/Desktop/Disjoint-CNN/env/lib/python3.10/site-packages/tensorflow/python/eager/execute.py:53\u001b[0m, in \u001b[0;36mquick_execute\u001b[0;34m(op_name, num_outputs, inputs, attrs, ctx, name)\u001b[0m\n\u001b[1;32m     51\u001b[0m \u001b[38;5;28;01mtry\u001b[39;00m:\n\u001b[1;32m     52\u001b[0m   ctx\u001b[38;5;241m.\u001b[39mensure_initialized()\n\u001b[0;32m---> 53\u001b[0m   tensors \u001b[38;5;241m=\u001b[39m pywrap_tfe\u001b[38;5;241m.\u001b[39mTFE_Py_Execute(ctx\u001b[38;5;241m.\u001b[39m_handle, device_name, op_name,\n\u001b[1;32m     54\u001b[0m                                       inputs, attrs, num_outputs)\n\u001b[1;32m     55\u001b[0m \u001b[38;5;28;01mexcept\u001b[39;00m core\u001b[38;5;241m.\u001b[39m_NotOkStatusException \u001b[38;5;28;01mas\u001b[39;00m e:\n\u001b[1;32m     56\u001b[0m   \u001b[38;5;28;01mif\u001b[39;00m name \u001b[38;5;129;01mis\u001b[39;00m \u001b[38;5;129;01mnot\u001b[39;00m \u001b[38;5;28;01mNone\u001b[39;00m:\n",
      "\u001b[0;31mUnknownError\u001b[0m: Graph execution error:\n\nDetected at node StatefulPartitionedCall defined at (most recent call last):\n  File \"/usr/lib/python3.10/runpy.py\", line 196, in _run_module_as_main\n\n  File \"/usr/lib/python3.10/runpy.py\", line 86, in _run_code\n\n  File \"/home/elnur/Desktop/Disjoint-CNN/env/lib/python3.10/site-packages/ipykernel_launcher.py\", line 18, in <module>\n\n  File \"/home/elnur/Desktop/Disjoint-CNN/env/lib/python3.10/site-packages/traitlets/config/application.py\", line 1075, in launch_instance\n\n  File \"/home/elnur/Desktop/Disjoint-CNN/env/lib/python3.10/site-packages/ipykernel/kernelapp.py\", line 739, in start\n\n  File \"/home/elnur/Desktop/Disjoint-CNN/env/lib/python3.10/site-packages/tornado/platform/asyncio.py\", line 205, in start\n\n  File \"/usr/lib/python3.10/asyncio/base_events.py\", line 603, in run_forever\n\n  File \"/usr/lib/python3.10/asyncio/base_events.py\", line 1909, in _run_once\n\n  File \"/usr/lib/python3.10/asyncio/events.py\", line 80, in _run\n\n  File \"/home/elnur/Desktop/Disjoint-CNN/env/lib/python3.10/site-packages/ipykernel/kernelbase.py\", line 545, in dispatch_queue\n\n  File \"/home/elnur/Desktop/Disjoint-CNN/env/lib/python3.10/site-packages/ipykernel/kernelbase.py\", line 534, in process_one\n\n  File \"/home/elnur/Desktop/Disjoint-CNN/env/lib/python3.10/site-packages/ipykernel/kernelbase.py\", line 437, in dispatch_shell\n\n  File \"/home/elnur/Desktop/Disjoint-CNN/env/lib/python3.10/site-packages/ipykernel/ipkernel.py\", line 359, in execute_request\n\n  File \"/home/elnur/Desktop/Disjoint-CNN/env/lib/python3.10/site-packages/ipykernel/kernelbase.py\", line 778, in execute_request\n\n  File \"/home/elnur/Desktop/Disjoint-CNN/env/lib/python3.10/site-packages/ipykernel/ipkernel.py\", line 446, in do_execute\n\n  File \"/home/elnur/Desktop/Disjoint-CNN/env/lib/python3.10/site-packages/ipykernel/zmqshell.py\", line 549, in run_cell\n\n  File \"/home/elnur/Desktop/Disjoint-CNN/env/lib/python3.10/site-packages/IPython/core/interactiveshell.py\", line 3075, in run_cell\n\n  File \"/home/elnur/Desktop/Disjoint-CNN/env/lib/python3.10/site-packages/IPython/core/interactiveshell.py\", line 3130, in _run_cell\n\n  File \"/home/elnur/Desktop/Disjoint-CNN/env/lib/python3.10/site-packages/IPython/core/async_helpers.py\", line 129, in _pseudo_sync_runner\n\n  File \"/home/elnur/Desktop/Disjoint-CNN/env/lib/python3.10/site-packages/IPython/core/interactiveshell.py\", line 3334, in run_cell_async\n\n  File \"/home/elnur/Desktop/Disjoint-CNN/env/lib/python3.10/site-packages/IPython/core/interactiveshell.py\", line 3517, in run_ast_nodes\n\n  File \"/home/elnur/Desktop/Disjoint-CNN/env/lib/python3.10/site-packages/IPython/core/interactiveshell.py\", line 3577, in run_code\n\n  File \"/tmp/ipykernel_2290774/4282388530.py\", line 25, in <module>\n\n  File \"/home/elnur/Desktop/Disjoint-CNN/env/lib/python3.10/site-packages/keras/src/utils/traceback_utils.py\", line 118, in error_handler\n\n  File \"/home/elnur/Desktop/Disjoint-CNN/env/lib/python3.10/site-packages/keras/src/backend/tensorflow/trainer.py\", line 513, in predict\n\n  File \"/home/elnur/Desktop/Disjoint-CNN/env/lib/python3.10/site-packages/keras/src/backend/tensorflow/trainer.py\", line 212, in one_step_on_data_distributed\n\nFailed to determine best cudnn convolution algorithm for:\n%cudnn-conv-bias-activation.22 = (f32[32,64,963,144]{3,2,1,0}, u8[0]{0}) custom-call(f32[32,1,970,144]{3,2,1,0} %pad.3, f32[64,1,8,1]{3,2,1,0} %transpose.20, f32[64]{0} %arg2.3), window={size=8x1}, dim_labels=bf01_oi01->bf01, custom_call_target=\"__cudnn$convBiasActivationForward\", metadata={op_type=\"Conv2D\" op_name=\"functional_1_1/conv2d_1/convolution\" source_file=\"/home/elnur/Desktop/Disjoint-CNN/env/lib/python3.10/site-packages/tensorflow/python/framework/ops.py\" source_line=1177}, backend_config={\"operation_queue_id\":\"0\",\"wait_on_operation_queues\":[],\"cudnn_conv_backend_config\":{\"conv_result_scale\":1,\"activation_mode\":\"kNone\",\"side_input_scale\":0,\"leakyrelu_alpha\":0}}\n\nOriginal error: RESOURCE_EXHAUSTED: Out of memory while trying to allocate 1152778240 bytes.\n\nTo ignore this failure and try to use a fallback algorithm (which may have suboptimal performance), use XLA_FLAGS=--xla_gpu_strict_conv_algorithm_picker=false.  Please also file a bug for the root cause of failing autotuning.\n\t [[{{node StatefulPartitionedCall}}]] [Op:__inference_one_step_on_data_distributed_22732]"
     ]
    }
   ],
   "source": [
    "import os\n",
    "import numpy as np\n",
    "import pandas as pd\n",
    "from aeon.datasets import load_classification\n",
    "from tensorflow import keras\n",
    "from sklearn.preprocessing import LabelEncoder\n",
    "\n",
    "from utils.tools import create_directory\n",
    "from utils.constants import datasets\n",
    "\n",
    "encoder = LabelEncoder()\n",
    "\n",
    "\n",
    "trainin_accs=pd.DataFrame({\n",
    "    \"datasets\":datasets,\n",
    "    \"acc\":datasets\n",
    "})\n",
    "# Hyper-Parameter Setting ----------------------------------------------------------------------------------------------\n",
    "classifier_name = \"Disjoint_CNN\"  # Choose the classifier name from aforementioned List\n",
    "# ----------------------------------------------------------------------------------------------------------------------\n",
    "for i in range(len(datasets)):\n",
    "    problem = datasets[i]\n",
    "    # Load Data --------------------------------------------------------------------------------------------------------\n",
    "    output_directory = os.getcwd() + '/Results_' + classifier_name + '/' + problem + '/1/'\n",
    "    create_directory(output_directory)\n",
    "    print(\"[Main] Problem: {}\".format(problem))\n",
    "    X_train, y_train = load_classification(problem, split='train')\n",
    "    model = keras.models.load_model(output_directory + 'best_model.keras')\n",
    "    preds = model.predict(X_train)\n",
    "    preds=np.argmax(preds,axis=1)\n",
    "    y_train = encoder.fit_transform(y_train)\n",
    "    acc = np.mean(preds == y_train)\n",
    "    print(acc)\n",
    "    trainin_accs[\"acc\"][i]=acc\n",
    "trainin_accs.to_csv(\"./train_accs.csv\")\n",
    "    \n",
    "    \n",
    "    \n"
   ]
  }
 ],
 "metadata": {
  "kernelspec": {
   "display_name": "env",
   "language": "python",
   "name": "python3"
  },
  "language_info": {
   "codemirror_mode": {
    "name": "ipython",
    "version": 3
   },
   "file_extension": ".py",
   "mimetype": "text/x-python",
   "name": "python",
   "nbconvert_exporter": "python",
   "pygments_lexer": "ipython3",
   "version": "3.10.12"
  }
 },
 "nbformat": 4,
 "nbformat_minor": 2
}
